<?xml version="1.0" ?>
<!-- =================================================================================== -->
<!-- |    This document was autogenerated by xacro from caramel.urdf.xacro             | -->
<!-- |    EDITING THIS FILE BY HAND IS NOT RECOMMENDED                                 | -->
<!-- =================================================================================== -->
<robot name="caramel">
  <link name="world"/>
  <link name="base_link">
    <visual>
      <origin rpy="0.0 0.0 0.0" xyz="0.0 0.0 -0.0208"/>
      <geometry>
        <mesh filename="package://caramel_description/meshes/base_link.dae"/>
      </geometry>
    </visual>
    <collision>
      <origin rpy="0.0 0.0 0.0" xyz="0.0 0.0 -0.0208"/>
      <geometry>
        <mesh filename="package://caramel_description/meshes/base_link.stl"/>
      </geometry>
    </collision>
    <inertial>
      <mass value="1.28"/>
      <origin rpy="0.0 0.0 0.0" xyz="0.0015 1.622e-4 0.0030000000000000027"/>
      <inertia ixx="0.00327123" ixy="-2.696e-6" ixz="-1.456e-5" iyy="0.00459934" iyz="-1.166e-5" izz="0.00718769"/>
    </inertial>
  </link>
  <link name="front_left_hip_fixed">
    <collision>
      <geometry>
        <sphere radius="0.001"/>
      </geometry>
    </collision>
    <inertial>
      <mass value="0.001"/>
      <inertia ixx="1e-6" ixy="0.0" ixz="0.0" iyy="1e-6" iyz="0.0" izz="1e-6"/>
    </inertial>
  </link>
  <joint name="front_left_hip_fixed_joint" type="fixed">
    <parent link="base_link"/>
    <child link="front_left_hip_fixed"/>
    <origin rpy="0.0 0.0 0.0" xyz="0.11455 0.07 0.0"/>
  </joint>
  <link name="front_left_hip">
    <visual>
      <origin rpy="0.0 0.0 0.0" xyz="0.0 0.0 0.0"/>
      <geometry>
        <mesh filename="package://caramel_description/meshes/hip.dae"/>
      </geometry>
    </visual>
    <collision>
      <origin rpy="0.0 0.0 0.0" xyz="-0.0149 0.0 0.0"/>
      <geometry>
        <box size="0.0538 0.036 0.036"/>
      </geometry>
    </collision>
    <inertial>
      <origin rpy="0.0 0.0 0.0" xyz="-0.011 0.0 0.0"/>
      <mass value="0.077"/>
      <inertia ixx="1.365e-5" ixy="-6.888e-7" ixz="2.025e-8" iyy="1.824e-5" iyz="-8.308e-9" izz="2.204e-5"/>
    </inertial>
  </link>
  <joint name="front_left_hip_roll_joint" type="revolute">
    <origin rpy="0.0 0.0 0.0" xyz="0.0 0.0 0.0"/>
    <parent link="front_left_hip_fixed"/>
    <child link="front_left_hip"/>
    <axis xyz="1 0 0"/>
    <limit effort="2" lower="-0.785375" upper="0.785375" velocity="5.75"/>
    <origin rpy="0.0 0.0 0.0" xyz="0.11455 0.07 0.0"/>
    <dynamics damping="0.1" friction="0.01"/>
  </joint>
  <link name="front_left_femur">
    <visual>
      <origin rpy="0.0 0.0 0.0 " xyz="0.0 0 -0.0053"/>
      <geometry>
        <mesh filename="package://caramel_description/meshes/left_femur.dae"/>
      </geometry>
    </visual>
    <collision>
      <origin rpy="0.0 0.0 0.0" xyz="0.0 0.0 -0.0053"/>
      <geometry>
        <mesh filename="package://caramel_description/meshes/femur.stl"/>
      </geometry>
    </collision>
    <inertial>
      <mass value="0.118"/>
      <origin rpy="0.0 0.0 0.0" xyz="-1.830e-4 0.002 -0.019"/>
      <inertia ixx="1.604e-4" ixy="-5.665e-8" ixz="0.00000115" iyy="1.647e-4" iyz="1.108e-5" izz="2.100e-5"/>
    </inertial>
  </link>
  <joint name="front_left_hip_pitch_joint" type="revolute">
    <origin rpy="0.0 0.785375 0.0" xyz="0 0.0415 0.0"/>
    <parent link="front_left_hip"/>
    <child link="front_left_femur"/>
    <axis xyz="0 1 0"/>
    <limit effort="2" lower="-1.0471666666666668" upper="1.0471666666666668" velocity="5.75"/>
    <dynamics damping="0.1" friction="0.01"/>
  </joint>
  <link name="front_left_tibia">
    <visual>
      <origin rpy="0.0 0.0 0.0" xyz="0.0 0.0 0.0 "/>
      <geometry>
        <mesh filename="package://caramel_description/meshes/tibia.dae"/>
      </geometry>
    </visual>
    <collision>
      <origin rpy="0.0 0.0 0.0" xyz="0.0 0.0 0.0 "/>
      <geometry>
        <mesh filename="package://caramel_description/meshes/tibia.stl"/>
      </geometry>
    </collision>
    <inertial>
      <mass value="0.035"/>
      <origin rpy="0.0 0.0 0.0" xyz="0.005 0.0 -0.06"/>
      <inertia ixx="8.305e-5" ixy="-4.892e-10" ixz="6.002e-6" iyy="8.447e-5" iyz="-4.088e-10" izz="2.687e-6"/>
    </inertial>
  </link>
  <joint name="front_left_elbow_joint" type="revolute">
    <origin rpy="0.0 -1.57075 0.0" xyz="0.00 0.0068 -0.12"/>
    <parent link="front_left_femur"/>
    <child link="front_left_tibia"/>
    <axis xyz="0 1 0"/>
    <limit effort="2" lower="-0.6283000000000001" upper="0.6283000000000001" velocity="5.75"/>
    <dynamics damping="0.00" friction="0.01"/>
  </joint>
  <link name="front_left_foot"/>
  <joint name="front_left_foot_joint" type="fixed">
    <parent link="front_left_tibia"/>
    <child link="front_left_foot"/>
    <origin rpy="0.0 0.785375 0.0" xyz="0.0 0.0 -0.12"/>
  </joint>
  <link name="front_right_hip_fixed">
    <collision>
      <geometry>
        <sphere radius="0.001"/>
      </geometry>
    </collision>
    <inertial>
      <mass value="0.001"/>
      <inertia ixx="1e-6" ixy="0.0" ixz="0.0" iyy="1e-6" iyz="0.0" izz="1e-6"/>
    </inertial>
  </link>
  <joint name="front_right_hip_fixed_joint" type="fixed">
    <parent link="base_link"/>
    <child link="front_right_hip_fixed"/>
    <origin rpy="0.0 0.0 0.0" xyz="0.11455 -0.07 0.0"/>
  </joint>
  <link name="front_right_hip">
    <visual>
      <origin rpy="3.1415 0.0 0.0" xyz="0.0 0.0 0.0"/>
      <geometry>
        <mesh filename="package://caramel_description/meshes/hip.dae"/>
      </geometry>
    </visual>
    <collision>
      <origin rpy="0.0 0.0 0.0" xyz="-0.0149 0.0 0.0"/>
      <geometry>
        <box size="0.0538 0.036 0.036"/>
      </geometry>
    </collision>
    <inertial>
      <origin rpy="3.1415 0.0 0.0" xyz="-0.011 0.0 0.0"/>
      <mass value="0.077"/>
      <inertia ixx="1.365e-5" ixy="-6.888e-7" ixz="2.025e-8" iyy="1.824e-5" iyz="-8.308e-9" izz="2.204e-5"/>
    </inertial>
  </link>
  <joint name="front_right_hip_roll_joint" type="revolute">
    <origin rpy="0.0 0.0 0.0" xyz="0.0 0.0 0.0"/>
    <parent link="front_right_hip_fixed"/>
    <child link="front_right_hip"/>
    <axis xyz="1 0 0"/>
    <limit effort="2" lower="-0.785375" upper="0.785375" velocity="5.75"/>
    <origin rpy="0.0 0.0 0.0" xyz="0.11455 -0.07 0.0"/>
    <dynamics damping="0.1" friction="0.01"/>
  </joint>
  <link name="front_right_femur">
    <visual>
      <origin rpy="0.0 0.0 0.0 " xyz="0.0 0 -0.0053"/>
      <geometry>
        <mesh filename="package://caramel_description/meshes/right_femur.dae"/>
      </geometry>
    </visual>
    <collision>
      <origin rpy="0.0 0.0 3.1415" xyz="0.0 0.0 -0.0053"/>
      <geometry>
        <mesh filename="package://caramel_description/meshes/femur.stl"/>
      </geometry>
    </collision>
    <inertial>
      <mass value="0.118"/>
      <origin rpy="0.0 0.0 0.0" xyz="-1.830e-4 -0.002 -0.019"/>
      <inertia ixx="1.604e-4" ixy="3.969e-8" ixz="1.151e-6" iyy="1.647e-4" iyz="-1.105e-5" izz="2.099e-5"/>
    </inertial>
  </link>
  <joint name="front_right_hip_pitch_joint" type="revolute">
    <origin rpy="0.0 0.785375 0.0" xyz="0 -0.0415 0.0"/>
    <parent link="front_right_hip"/>
    <child link="front_right_femur"/>
    <axis xyz="0 1 0"/>
    <limit effort="2" lower="-1.0471666666666668" upper="1.0471666666666668" velocity="5.75"/>
    <dynamics damping="0.1" friction="0.01"/>
  </joint>
  <link name="front_right_tibia">
    <visual>
      <origin rpy="0.0 0.0 0.0" xyz="0.0 0.0 0.0 "/>
      <geometry>
        <mesh filename="package://caramel_description/meshes/tibia.dae"/>
      </geometry>
    </visual>
    <collision>
      <origin rpy="0.0 0.0 0.0" xyz="0.0 0.0 0.0 "/>
      <geometry>
        <mesh filename="package://caramel_description/meshes/tibia.stl"/>
      </geometry>
    </collision>
    <inertial>
      <mass value="0.035"/>
      <origin rpy="0.0 0.0 0.0" xyz="0.005 0.0 -0.06"/>
      <inertia ixx="8.305e-5" ixy="-4.892e-10" ixz="6.002e-6" iyy="8.447e-5" iyz="-4.088e-10" izz="2.687e-6"/>
    </inertial>
  </link>
  <joint name="front_right_elbow_joint" type="revolute">
    <origin rpy="0.0 -1.57075 0.0" xyz="0.00 -0.0068 -0.12"/>
    <parent link="front_right_femur"/>
    <child link="front_right_tibia"/>
    <axis xyz="0 1 0"/>
    <limit effort="2" lower="-0.6283000000000001" upper="0.6283000000000001" velocity="5.75"/>
    <dynamics damping="0.00" friction="0.01"/>
  </joint>
  <link name="front_right_foot"/>
  <joint name="front_right_foot_joint" type="fixed">
    <parent link="front_right_tibia"/>
    <child link="front_right_foot"/>
    <origin rpy="0.0 0.785375 0.0" xyz="0.0 0.0 -0.12"/>
  </joint>
  <link name="back_left_hip_fixed">
    <collision>
      <geometry>
        <sphere radius="0.001"/>
      </geometry>
    </collision>
    <inertial>
      <mass value="0.001"/>
      <inertia ixx="1e-6" ixy="0.0" ixz="0.0" iyy="1e-6" iyz="0.0" izz="1e-6"/>
    </inertial>
  </link>
  <joint name="back_left_hip_fixed_joint" type="fixed">
    <parent link="base_link"/>
    <child link="back_left_hip_fixed"/>
    <origin rpy="0.0 0.0 0.0" xyz="-0.11455 0.07 0.0"/>
  </joint>
  <link name="back_left_hip">
    <visual>
      <origin rpy="3.1415 0.0 3.1415" xyz="0.0 0.0 0.0"/>
      <geometry>
        <mesh filename="package://caramel_description/meshes/hip.dae"/>
      </geometry>
    </visual>
    <collision>
      <origin rpy="0.0 0.0 0.0" xyz="0.0149 0.0 0.0"/>
      <geometry>
        <box size="0.0538 0.036 0.036"/>
      </geometry>
    </collision>
    <inertial>
      <origin rpy="3.1415 0.0 3.1415" xyz="0.011 0.0 0.0"/>
      <mass value="0.077"/>
      <inertia ixx="1.365e-5" ixy="-6.888e-7" ixz="2.025e-8" iyy="1.824e-5" iyz="-8.308e-9" izz="2.204e-5"/>
    </inertial>
  </link>
  <joint name="back_left_hip_roll_joint" type="revolute">
    <origin rpy="0.0 0.0 0.0" xyz="0.0 0.0 0.0"/>
    <parent link="back_left_hip_fixed"/>
    <child link="back_left_hip"/>
    <axis xyz="1 0 0"/>
    <limit effort="2" lower="-0.785375" upper="0.785375" velocity="5.75"/>
    <origin rpy="0.0 0.0 0.0" xyz="-0.11455 0.07 0.0"/>
    <dynamics damping="0.1" friction="0.01"/>
  </joint>
  <link name="back_left_femur">
    <visual>
      <origin rpy="0.0 0.0 0.0 " xyz="0.0 0 -0.0053"/>
      <geometry>
        <mesh filename="package://caramel_description/meshes/left_femur.dae"/>
      </geometry>
    </visual>
    <collision>
      <origin rpy="0.0 0.0 0.0" xyz="0.0 0.0 -0.0053"/>
      <geometry>
        <mesh filename="package://caramel_description/meshes/femur.stl"/>
      </geometry>
    </collision>
    <inertial>
      <mass value="0.118"/>
      <origin rpy="0.0 0.0 0.0" xyz="-1.830e-4 0.002 -0.019"/>
      <inertia ixx="1.604e-4" ixy="-5.665e-8" ixz="0.00000115" iyy="1.647e-4" iyz="1.108e-5" izz="2.100e-5"/>
    </inertial>
  </link>
  <joint name="back_left_hip_pitch_joint" type="revolute">
    <origin rpy="0.0 0.785375 0.0" xyz="0 0.0415 0.0"/>
    <parent link="back_left_hip"/>
    <child link="back_left_femur"/>
    <axis xyz="0 1 0"/>
    <limit effort="2" lower="-1.0471666666666668" upper="1.0471666666666668" velocity="5.75"/>
    <dynamics damping="0.1" friction="0.01"/>
  </joint>
  <link name="back_left_tibia">
    <visual>
      <origin rpy="0.0 0.0 0.0" xyz="0.0 0.0 0.0 "/>
      <geometry>
        <mesh filename="package://caramel_description/meshes/tibia.dae"/>
      </geometry>
    </visual>
    <collision>
      <origin rpy="0.0 0.0 0.0" xyz="0.0 0.0 0.0 "/>
      <geometry>
        <mesh filename="package://caramel_description/meshes/tibia.stl"/>
      </geometry>
    </collision>
    <inertial>
      <mass value="0.035"/>
      <origin rpy="0.0 0.0 0.0" xyz="0.005 0.0 -0.06"/>
      <inertia ixx="8.305e-5" ixy="-4.892e-10" ixz="6.002e-6" iyy="8.447e-5" iyz="-4.088e-10" izz="2.687e-6"/>
    </inertial>
  </link>
  <joint name="back_left_elbow_joint" type="revolute">
    <origin rpy="0.0 -1.57075 0.0" xyz="0.00 0.0068 -0.12"/>
    <parent link="back_left_femur"/>
    <child link="back_left_tibia"/>
    <axis xyz="0 1 0"/>
    <limit effort="2" lower="-0.6283000000000001" upper="0.6283000000000001" velocity="5.75"/>
    <dynamics damping="0.00" friction="0.01"/>
  </joint>
  <link name="back_left_foot"/>
  <joint name="back_left_foot_joint" type="fixed">
    <parent link="back_left_tibia"/>
    <child link="back_left_foot"/>
    <origin rpy="0.0 0.785375 0.0" xyz="0.0 0.0 -0.12"/>
  </joint>
  <link name="back_right_hip_fixed">
    <collision>
      <geometry>
        <sphere radius="0.001"/>
      </geometry>
    </collision>
    <inertial>
      <mass value="0.001"/>
      <inertia ixx="1e-6" ixy="0.0" ixz="0.0" iyy="1e-6" iyz="0.0" izz="1e-6"/>
    </inertial>
  </link>
  <joint name="back_right_hip_fixed_joint" type="fixed">
    <parent link="base_link"/>
    <child link="back_right_hip_fixed"/>
    <origin rpy="0.0 0.0 0.0" xyz="-0.11455 -0.07 0.0"/>
  </joint>
  <link name="back_right_hip">
    <visual>
      <origin rpy="0.0 0.0 3.1415" xyz="0.0 0.0 0.0"/>
      <geometry>
        <mesh filename="package://caramel_description/meshes/hip.dae"/>
      </geometry>
    </visual>
    <collision>
      <origin rpy="0.0 0.0 0.0" xyz="0.0149 0.0 0.0"/>
      <geometry>
        <box size="0.0538 0.036 0.036"/>
      </geometry>
    </collision>
    <inertial>
      <origin rpy="0.0 0.0 3.1415" xyz="0.011 0.0 0.0"/>
      <mass value="0.077"/>
      <inertia ixx="1.365e-5" ixy="-6.888e-7" ixz="2.025e-8" iyy="1.824e-5" iyz="-8.308e-9" izz="2.204e-5"/>
    </inertial>
  </link>
  <joint name="back_right_hip_roll_joint" type="revolute">
    <origin rpy="0.0 0.0 0.0" xyz="0.0 0.0 0.0"/>
    <parent link="back_right_hip_fixed"/>
    <child link="back_right_hip"/>
    <axis xyz="1 0 0"/>
    <limit effort="2" lower="-0.785375" upper="0.785375" velocity="5.75"/>
    <origin rpy="0.0 0.0 0.0" xyz="-0.11455 -0.07 0.0"/>
    <dynamics damping="0.1" friction="0.01"/>
  </joint>
  <link name="back_right_femur">
    <visual>
      <origin rpy="0.0 0.0 0.0 " xyz="0.0 0 -0.0053"/>
      <geometry>
        <mesh filename="package://caramel_description/meshes/right_femur.dae"/>
      </geometry>
    </visual>
    <collision>
      <origin rpy="0.0 0.0 3.1415" xyz="0.0 0.0 -0.0053"/>
      <geometry>
        <mesh filename="package://caramel_description/meshes/femur.stl"/>
      </geometry>
    </collision>
    <inertial>
      <mass value="0.118"/>
      <origin rpy="0.0 0.0 0.0" xyz="-1.830e-4 -0.002 -0.019"/>
      <inertia ixx="1.604e-4" ixy="3.969e-8" ixz="1.151e-6" iyy="1.647e-4" iyz="-1.105e-5" izz="2.099e-5"/>
    </inertial>
  </link>
  <joint name="back_right_hip_pitch_joint" type="revolute">
    <origin rpy="0.0 0.785375 0.0" xyz="0 -0.0415 0.0"/>
    <parent link="back_right_hip"/>
    <child link="back_right_femur"/>
    <axis xyz="0 1 0"/>
    <limit effort="2" lower="-1.0471666666666668" upper="1.0471666666666668" velocity="5.75"/>
    <dynamics damping="0.1" friction="0.01"/>
  </joint>
  <link name="back_right_tibia">
    <visual>
      <origin rpy="0.0 0.0 0.0" xyz="0.0 0.0 0.0 "/>
      <geometry>
        <mesh filename="package://caramel_description/meshes/tibia.dae"/>
      </geometry>
    </visual>
    <collision>
      <origin rpy="0.0 0.0 0.0" xyz="0.0 0.0 0.0 "/>
      <geometry>
        <mesh filename="package://caramel_description/meshes/tibia.stl"/>
      </geometry>
    </collision>
    <inertial>
      <mass value="0.035"/>
      <origin rpy="0.0 0.0 0.0" xyz="0.005 0.0 -0.06"/>
      <inertia ixx="8.305e-5" ixy="-4.892e-10" ixz="6.002e-6" iyy="8.447e-5" iyz="-4.088e-10" izz="2.687e-6"/>
    </inertial>
  </link>
  <joint name="back_right_elbow_joint" type="revolute">
    <origin rpy="0.0 -1.57075 0.0" xyz="0.00 -0.0068 -0.12"/>
    <parent link="back_right_femur"/>
    <child link="back_right_tibia"/>
    <axis xyz="0 1 0"/>
    <limit effort="2" lower="-0.6283000000000001" upper="0.6283000000000001" velocity="5.75"/>
    <dynamics damping="0.00" friction="0.01"/>
  </joint>
  <link name="back_right_foot"/>
  <joint name="back_right_foot_joint" type="fixed">
    <parent link="back_right_tibia"/>
    <child link="back_right_foot"/>
    <origin rpy="0.0 0.785375 0.0" xyz="0.0 0.0 -0.12"/>
  </joint>
  <link name="imu_link"/>
  <joint name="imu_joint" type="fixed">
    <origin rpy="0.0 0.0 0.0" xyz="0.0 0.0 0.0"/>
    <parent link="base_link"/>
    <child link="imu_link"/>
    <axis xyz="0.075 0.0 0.0738"/>
  </joint>

  <joint name="joint_world" type="fixed">
    <parent link="world"/>
    <child link="base_link"/>
    <origin rpy="0 0 0" xyz="0 0 0.25"/>
  </joint>
</robot>
